[2021-01-21 06:23:21,436] {{taskinstance.py:655}} INFO - Dependencies all met for <TaskInstance: MarketVol.error_log_analyzer 2021-01-20T02:30:00+00:00 [queued]>
[2021-01-21 06:23:21,447] {{taskinstance.py:655}} INFO - Dependencies all met for <TaskInstance: MarketVol.error_log_analyzer 2021-01-20T02:30:00+00:00 [queued]>
[2021-01-21 06:23:21,448] {{taskinstance.py:866}} INFO - 
--------------------------------------------------------------------------------
[2021-01-21 06:23:21,449] {{taskinstance.py:867}} INFO - Starting attempt 1 of 1
[2021-01-21 06:23:21,450] {{taskinstance.py:868}} INFO - 
--------------------------------------------------------------------------------
[2021-01-21 06:23:21,457] {{taskinstance.py:887}} INFO - Executing <Task(BashOperator): error_log_analyzer> on 2021-01-20T02:30:00+00:00
[2021-01-21 06:23:21,461] {{standard_task_runner.py:53}} INFO - Started process 285 to run task
[2021-01-21 06:23:21,506] {{logging_mixin.py:112}} INFO - Running %s on host %s <TaskInstance: MarketVol.error_log_analyzer 2021-01-20T02:30:00+00:00 [running]> 99b7c767768b
[2021-01-21 06:23:21,520] {{bash_operator.py:82}} INFO - Tmp dir root location: 
 /tmp
[2021-01-21 06:23:21,522] {{bash_operator.py:105}} INFO - Temporary script location: /tmp/airflowtmpl6dtlydp/error_log_analyzerwsqqjkic
[2021-01-21 06:23:21,523] {{bash_operator.py:115}} INFO - Running command: python $(pwd)/script/log_analyzer.py -p $(pwd)/logs/MarketVol -v 0
[2021-01-21 06:23:21,531] {{bash_operator.py:122}} INFO - Output:
[2021-01-21 06:23:21,550] {{bash_operator.py:126}} INFO - python: can't open file '/tmp/airflowtmpl6dtlydp/script/log_analyzer.py': [Errno 2] No such file or directory
[2021-01-21 06:23:21,552] {{bash_operator.py:130}} INFO - Command exited with return code 2
[2021-01-21 06:23:21,558] {{taskinstance.py:1128}} ERROR - Bash command failed
Traceback (most recent call last):
  File "/usr/local/lib/python3.7/site-packages/airflow/models/taskinstance.py", line 966, in _run_raw_task
    result = task_copy.execute(context=context)
  File "/usr/local/lib/python3.7/site-packages/airflow/operators/bash_operator.py", line 134, in execute
    raise AirflowException("Bash command failed")
airflow.exceptions.AirflowException: Bash command failed
[2021-01-21 06:23:21,564] {{taskinstance.py:1185}} INFO - Marking task as FAILED.dag_id=MarketVol, task_id=error_log_analyzer, execution_date=20210120T023000, start_date=20210121T062321, end_date=20210121T062321
[2021-01-21 06:23:31,430] {{logging_mixin.py:112}} INFO - [2021-01-21 06:23:31,430] {{local_task_job.py:103}} INFO - Task exited with return code 1
